2023-01-03 17:11:17,507 INFO    StreamThr :32517 [internal.py:wandb_internal():87] W&B internal server running at pid: 32517, started at: 2023-01-03 17:11:17.504948
2023-01-03 17:11:17,508 DEBUG   HandlerThread:32517 [handler.py:handle_request():139] handle_request: status
2023-01-03 17:11:17,510 DEBUG   SenderThread:32517 [sender.py:send_request():317] send_request: status
2023-01-03 17:11:17,511 DEBUG   SenderThread:32517 [sender.py:send():303] send: header
2023-01-03 17:11:17,511 INFO    WriterThread:32517 [datastore.py:open_for_write():75] open: /Volumes/Work Disk Janina Mattes/DEV/University/ASP/ml-explorer-drone/PPO/ppo_torch/wandb/run-20230103_171117-cfylaxka/run-cfylaxka.wandb
2023-01-03 17:11:17,517 DEBUG   SenderThread:32517 [sender.py:send():303] send: run
2023-01-03 17:11:17,520 INFO    SenderThread:32517 [sender.py:_maybe_setup_resume():593] checking resume status for drone-mechanics/drone-mechanics-ppo-OpenAIGym/cfylaxka
2023-01-03 17:11:18,203 ERROR   SenderThread:32517 [internal_api.py:execute():212] 409 response executing GraphQL.
2023-01-03 17:11:18,203 ERROR   SenderThread:32517 [internal_api.py:execute():213] {"errors":[{"message":"run drone-mechanics/drone-mechanics-ppo-OpenAIGym/cfylaxka was previously created and deleted; try a new run name","path":["upsertBucket"]}],"data":{"upsertBucket":null}}
2023-01-03 17:11:19,568 ERROR   SenderThread:32517 [internal_api.py:execute():212] 409 response executing GraphQL.
2023-01-03 17:11:19,568 ERROR   SenderThread:32517 [internal_api.py:execute():213] {"errors":[{"message":"run drone-mechanics/drone-mechanics-ppo-OpenAIGym/cfylaxka was previously created and deleted; try a new run name","path":["upsertBucket"]}],"data":{"upsertBucket":null}}
2023-01-03 17:11:21,866 ERROR   SenderThread:32517 [internal_api.py:execute():212] 409 response executing GraphQL.
2023-01-03 17:11:21,867 ERROR   SenderThread:32517 [internal_api.py:execute():213] {"errors":[{"message":"run drone-mechanics/drone-mechanics-ppo-OpenAIGym/cfylaxka was previously created and deleted; try a new run name","path":["upsertBucket"]}],"data":{"upsertBucket":null}}
2023-01-03 17:11:21,867 ERROR   SenderThread:32517 [retry.py:__call__():154] Retry attempt failed:
Traceback (most recent call last):
  File "/Users/janinaalicamattes/miniforge3/envs/pytorch-ppo-research/lib/python3.10/site-packages/wandb/sdk/lib/retry.py", line 113, in __call__
    result = self._call_fn(*args, **kwargs)
  File "/Users/janinaalicamattes/miniforge3/envs/pytorch-ppo-research/lib/python3.10/site-packages/wandb/sdk/internal/internal_api.py", line 209, in execute
    return self.client.execute(*args, **kwargs)  # type: ignore
  File "/Users/janinaalicamattes/miniforge3/envs/pytorch-ppo-research/lib/python3.10/site-packages/wandb/vendor/gql-0.2.0/wandb_gql/client.py", line 52, in execute
    result = self._get_result(document, *args, **kwargs)
  File "/Users/janinaalicamattes/miniforge3/envs/pytorch-ppo-research/lib/python3.10/site-packages/wandb/vendor/gql-0.2.0/wandb_gql/client.py", line 60, in _get_result
    return self.transport.execute(document, *args, **kwargs)
  File "/Users/janinaalicamattes/miniforge3/envs/pytorch-ppo-research/lib/python3.10/site-packages/wandb/vendor/gql-0.2.0/wandb_gql/transport/requests.py", line 39, in execute
    request.raise_for_status()
  File "/Users/janinaalicamattes/miniforge3/envs/pytorch-ppo-research/lib/python3.10/site-packages/requests/models.py", line 1021, in raise_for_status
    raise HTTPError(http_error_msg, response=self)
requests.exceptions.HTTPError: 409 Client Error: Conflict for url: https://api.wandb.ai/graphql
2023-01-03 17:11:22,543 DEBUG   HandlerThread:32517 [handler.py:handle_request():139] handle_request: keepalive
2023-01-03 17:11:26,812 ERROR   SenderThread:32517 [internal_api.py:execute():212] 409 response executing GraphQL.
2023-01-03 17:11:26,812 ERROR   SenderThread:32517 [internal_api.py:execute():213] {"errors":[{"message":"run drone-mechanics/drone-mechanics-ppo-OpenAIGym/cfylaxka was previously created and deleted; try a new run name","path":["upsertBucket"]}],"data":{"upsertBucket":null}}
2023-01-03 17:11:27,562 DEBUG   HandlerThread:32517 [handler.py:handle_request():139] handle_request: keepalive
2023-01-03 17:11:32,576 DEBUG   HandlerThread:32517 [handler.py:handle_request():139] handle_request: keepalive
2023-01-03 17:11:35,728 ERROR   SenderThread:32517 [internal_api.py:execute():212] 409 response executing GraphQL.
2023-01-03 17:11:35,732 ERROR   SenderThread:32517 [internal_api.py:execute():213] {"errors":[{"message":"run drone-mechanics/drone-mechanics-ppo-OpenAIGym/cfylaxka was previously created and deleted; try a new run name","path":["upsertBucket"]}],"data":{"upsertBucket":null}}
2023-01-03 17:11:37,602 DEBUG   HandlerThread:32517 [handler.py:handle_request():139] handle_request: keepalive
2023-01-03 17:11:39,723 DEBUG   HandlerThread:32517 [handler.py:handle_request():139] handle_request: poll_exit
2023-01-03 17:11:44,743 DEBUG   HandlerThread:32517 [handler.py:handle_request():139] handle_request: keepalive
2023-01-03 17:11:49,762 DEBUG   HandlerThread:32517 [handler.py:handle_request():139] handle_request: keepalive
2023-01-03 17:11:54,706 ERROR   SenderThread:32517 [internal_api.py:execute():212] 409 response executing GraphQL.
2023-01-03 17:11:54,706 ERROR   SenderThread:32517 [internal_api.py:execute():213] {"errors":[{"message":"run drone-mechanics/drone-mechanics-ppo-OpenAIGym/cfylaxka was previously created and deleted; try a new run name","path":["upsertBucket"]}],"data":{"upsertBucket":null}}
2023-01-03 17:11:54,781 DEBUG   HandlerThread:32517 [handler.py:handle_request():139] handle_request: keepalive
2023-01-03 17:11:58,656 WARNING StreamThr :32517 [internal.py:is_dead():386] Internal process exiting, parent pid 32510 disappeared
2023-01-03 17:11:58,656 ERROR   StreamThr :32517 [internal.py:wandb_internal():146] Internal process shutdown.
2023-01-03 17:11:58,787 INFO    HandlerThread:32517 [handler.py:finish():814] shutting down handler
2023-01-03 17:11:58,803 INFO    WriterThread:32517 [datastore.py:close():279] close: /Volumes/Work Disk Janina Mattes/DEV/University/ASP/ml-explorer-drone/PPO/ppo_torch/wandb/run-20230103_171117-cfylaxka/run-cfylaxka.wandb
2023-01-03 17:12:30,663 ERROR   SenderThread:32517 [internal_api.py:execute():212] 409 response executing GraphQL.
2023-01-03 17:12:30,663 ERROR   SenderThread:32517 [internal_api.py:execute():213] {"errors":[{"message":"run drone-mechanics/drone-mechanics-ppo-OpenAIGym/cfylaxka was previously created and deleted; try a new run name","path":["upsertBucket"]}],"data":{"upsertBucket":null}}
2023-01-03 17:13:42,304 ERROR   SenderThread:32517 [internal_api.py:execute():212] 409 response executing GraphQL.
2023-01-03 17:13:42,308 ERROR   SenderThread:32517 [internal_api.py:execute():213] {"errors":[{"message":"run drone-mechanics/drone-mechanics-ppo-OpenAIGym/cfylaxka was previously created and deleted; try a new run name","path":["upsertBucket"]}],"data":{"upsertBucket":null}}
2023-01-03 17:13:42,308 ERROR   StreamThr :32517 [internal.py:wandb_internal():162] Thread SenderThread:
Traceback (most recent call last):
  File "/Users/janinaalicamattes/miniforge3/envs/pytorch-ppo-research/lib/python3.10/site-packages/wandb/apis/normalize.py", line 26, in wrapper
    return func(*args, **kwargs)
  File "/Users/janinaalicamattes/miniforge3/envs/pytorch-ppo-research/lib/python3.10/site-packages/wandb/sdk/internal/internal_api.py", line 1515, in upsert_run
    response = self.gql(
  File "/Users/janinaalicamattes/miniforge3/envs/pytorch-ppo-research/lib/python3.10/site-packages/wandb/sdk/lib/retry.py", line 113, in __call__
    result = self._call_fn(*args, **kwargs)
  File "/Users/janinaalicamattes/miniforge3/envs/pytorch-ppo-research/lib/python3.10/site-packages/wandb/sdk/internal/internal_api.py", line 209, in execute
    return self.client.execute(*args, **kwargs)  # type: ignore
  File "/Users/janinaalicamattes/miniforge3/envs/pytorch-ppo-research/lib/python3.10/site-packages/wandb/vendor/gql-0.2.0/wandb_gql/client.py", line 52, in execute
    result = self._get_result(document, *args, **kwargs)
  File "/Users/janinaalicamattes/miniforge3/envs/pytorch-ppo-research/lib/python3.10/site-packages/wandb/vendor/gql-0.2.0/wandb_gql/client.py", line 60, in _get_result
    return self.transport.execute(document, *args, **kwargs)
  File "/Users/janinaalicamattes/miniforge3/envs/pytorch-ppo-research/lib/python3.10/site-packages/wandb/vendor/gql-0.2.0/wandb_gql/transport/requests.py", line 39, in execute
    request.raise_for_status()
  File "/Users/janinaalicamattes/miniforge3/envs/pytorch-ppo-research/lib/python3.10/site-packages/requests/models.py", line 1021, in raise_for_status
    raise HTTPError(http_error_msg, response=self)
requests.exceptions.HTTPError: 409 Client Error: Conflict for url: https://api.wandb.ai/graphql

During handling of the above exception, another exception occurred:

Traceback (most recent call last):
  File "/Users/janinaalicamattes/miniforge3/envs/pytorch-ppo-research/lib/python3.10/site-packages/wandb/sdk/internal/internal_util.py", line 49, in run
    self._run()
  File "/Users/janinaalicamattes/miniforge3/envs/pytorch-ppo-research/lib/python3.10/site-packages/wandb/sdk/internal/internal_util.py", line 100, in _run
    self._process(record)
  File "/Users/janinaalicamattes/miniforge3/envs/pytorch-ppo-research/lib/python3.10/site-packages/wandb/sdk/internal/internal.py", line 309, in _process
    self._sm.send(record)
  File "/Users/janinaalicamattes/miniforge3/envs/pytorch-ppo-research/lib/python3.10/site-packages/wandb/sdk/internal/sender.py", line 305, in send
    send_handler(record)
  File "/Users/janinaalicamattes/miniforge3/envs/pytorch-ppo-research/lib/python3.10/site-packages/wandb/sdk/internal/sender.py", line 797, in send_run
    self._init_run(run, config_value_dict)
  File "/Users/janinaalicamattes/miniforge3/envs/pytorch-ppo-research/lib/python3.10/site-packages/wandb/sdk/internal/sender.py", line 823, in _init_run
    server_run, inserted, server_messages = self._api.upsert_run(
  File "/Users/janinaalicamattes/miniforge3/envs/pytorch-ppo-research/lib/python3.10/site-packages/wandb/apis/normalize.py", line 28, in wrapper
    raise CommError(err.response, err)
wandb.errors.CommError: <Response [409]>
